Workbook

Sheet RTC
A1: PPA Form 13 | G1: PPA-FO-FR-013
A3: PAROLE AND PROBATION ADMINISTRATION
A4: {Office_Name}
A5: IBP Building, New Capitol Site, Tagbilaran City
A6: Tel No. (038) 500-1146 ppo07.tagbilarancity@gmail.com https://probation.gov.ph
A8: REQUEST FOR RECORDS CHECK
G10: DATE: | H10: {Export_Date}
A11: TO: | B11: The Clerk of Court
B12: RTC OCC
B13: Tagbilaran City, Bohol
A15: SIR/MA'AM:
B16: May we be furnished derogatory records of the applicant for probation named below:
B18: NAME OF PETITIONER | E18: {Name_of_Petitioner}
B19: TRUE NAME | E19: {True_Name}
B20: ALIAS / ES | E20: {Alias}
B21: SEX | E21: {Sex}
B22: AGE | E22: {Age}
B23: CIVIL STATUS | E23: {Civil_Status}
B24: DATE OF BIRTH | E24: {Birthday}
B25: PLACE OF BIRTH | E25: {Birthplace}
B26: PRESENT ADDRESS | E26: {Present_Address}
B27: PERMANENT ADDRESS | E27: {Permanent_Address}
B28: CRIMINAL CASE NO. / S | E28: {Criminal_Case_Numbers}
B29: OFFENSES | E29: {Offenses}
... B32: NAME OF PARENTS | E32: {Father}
E33: {Mother}
F35: {Investigating_Officer}
F36: Investigating Officer-on-Case
A37: Noted:
B39: Chief Probation and Parole Officer
F42: Date
A43: TO: | B43: {Office_Name}
B44: IBP Bldg., E.B. Aumentado St., Tagbilaran City, Bohol
A46: FROM: | B46: =B11 -> The Clerk of Court
B47: =B12 -> RTC OCC
B48: Tagbilaran City, Bohol
A49: Records check revealed the following as of this date:
B50: ( ) No records on file
B51: ( ) No derogatory record
B52: ( ) Derogatory record stated at the back of this page
...

Sheet MTCC
A1: PPA Form 13 | G1: PPA-FO-FR-013
A3: PAROLE AND PROBATION ADMINISTRATION
A4: {Office_Name}
A5: IBP Building, New Capitol Site, Tagbilaran City
A6: Tel No. (038) 500-1146 ppo07.tagbilarancity@gmail.com https://probation.gov.ph
A8: REQUEST FOR RECORDS CHECK
G10: DATE: | H10: =RTC!H10 -> 43777
A11: TO: | B11: The Clerk of Court
B12: MTCC OCC
B13: Cebu City
A15: SIR/MA'AM:
B16: May we be furnished derogatory records of the applicant for probation named below:
B18: NAME OF PETITIONER | E18: =RTC!E18 -> RISALINDA PACA ABELLAR
B19: TRUE NAME | E19: =RTC!E19 -> RISALINDA PACA ABELLAR
B20: ALIAS / ES | E20: =RTC!E20 -> Risa
B21: SEX | E21: =RTC!E21 -> Female
B22: AGE | E22: =RTC!E22 -> 51
B23: CIVIL STATUS | E23: =RTC!E23 -> n/a
B24: DATE OF BIRTH | E24: =RTC!E24 -> 25073
B25: PLACE OF BIRTH | E25: =RTC!E25 -> Ermita, Cebu City, Cebu
B26: PRESENT ADDRESS | E26: =RTC!E26 -> detained at PNP Cordova, Cebu
B27: PERMANENT ADDRESS | E27: =RTC!E27 -> 25D Ermita Beach, Cebu City, Cebu
B28: CRIMINAL CASE NO. / S | E28: =RTC!E28 -> COR-38395 and COR-38397
B29: OFFENSES | E29: =RTC!E29 -> Violation of Secs. 5 & 11 of RA 9165
... B32: NAME OF PARENTS | E32: =RTC!E32 -> n/a
E33: =RTC!E33 -> n/a
F35: {Investigating_Officer}
F36: Investigating Officer-on-Case
A37: Noted:
B39: Chief Probation and Parole Officer
F42: Date
A43: TO: | B43: {Office_Name}
B44: IBP Bldg., E.B. Aumentado St., Tagbilaran City, Bohol
A46: FROM: | B46: =B11 -> The Clerk of Court
B47: =B12 -> MTCC OCC
B48: Tagbilaran City, Bohol
A49: Records check revealed the following as of this date:
B50: ( ) No records on file
B51: ( ) No derogatory record
B52: ( ) Derogatory record stated at the back of this page
...

Sheet City Pros
A1: PPA Form 13 | G1: PPA-FO-FR-013
A4: {Office_Name}
A5: Tagbilaran City Parole and Probation Office
A6: IBP Building, New Capitol Site, Tagbilaran City
A7: Tel No. (038) 500-1146 ppo07.tagbilarancity@gmail.com https://probation.gov.ph
A8: REQUEST FOR RECORDS CHECK
G10: DATE: | H10: =RTC!H10 -> 43777
A11: TO: | B11: The Records Officer
B12: City Prosecutors Office
B13: Cebu City
A15: SIR/MA'AM:
B16: May we be furnished derogatory records of the applicant for probation named below:
B18: NAME OF PETITIONER | E18: =RTC!E18 -> RISALINDA PACA ABELLAR
B19: TRUE NAME | E19: =RTC!E19 -> RISALINDA PACA ABELLAR
B20: ALIAS / ES | E20: =RTC!E20 -> Risa
B21: SEX | E21: =RTC!E21 -> Female
B22: AGE | E22: =RTC!E22 -> 51
B23: CIVIL STATUS | E23: =RTC!E23 -> n/a
B24: DATE OF BIRTH | E24: =RTC!E24 -> 25073
B25: PLACE OF BIRTH | E25: =RTC!E25 -> Ermita, Cebu City, Cebu
B26: PRESENT ADDRESS | E26: =RTC!E26 -> detained at PNP Cordova, Cebu
B27: PERMANENT ADDRESS | E27: =RTC!E27 -> 25D Ermita Beach, Cebu City, Cebu
B28: CRIMINAL CASE NO. / S | E28: =RTC!E28 -> COR-38395 and COR-38397
B29: OFFENSES | E29: =RTC!E29 -> Violation of Secs. 5 & 11 of RA 9165
... B32: NAME OF PARENTS | E32: =RTC!E32 -> n/a
E33: =RTC!E33 -> n/a
F35: {Investigating_Officer}
F36: Investigating Officer-on-Case
A37: Noted:
B39: Chief Probation and Parole Officer
F42: Date
A43: TO: | B43: {Office_Name}
B44: IBP Bldg., E.B. Aumentado St., Tagbilaran City, Bohol
A46: FROM: | B46: =B11 -> The Records Officer
B47: =B12 -> City Prosecutors Office
B48: Tagbilaran City, Bohol
A49: Records check revealed the following as of this date:
B50: ( ) No records on file
B51: ( ) No derogatory record
B52: ( ) Derogatory record stated at the back of this page
...

Sheet PNP-2
A1: PPA Form 13 | G1: PPA-FO-FR-013
A4: {Office_Name}
A5: Tagbilaran City Parole and Probation Office
A6: IBP Building, New Capitol Site, Tagbilaran City
A7: Tel No. (038) 500-1146 ppo07.tagbilarancity@gmail.com https://probation.gov.ph
A8: REQUEST FOR RECORDS CHECK
G10: DATE: | H10: =RTC!H10 -> 43777
A11: TO: | B11: THE CHIEF, PNP-CRMEU
B12: Camp Sotero Cabahug
B13: Cebu City
A15: SIR/MA'AM:
B16: May we be furnished derogatory records of the applicant for probation named below:
B18: NAME OF PETITIONER | E18: =RTC!E18 -> RISALINDA PACA ABELLAR
B19: TRUE NAME | E19: =RTC!E19 -> RISALINDA PACA ABELLAR
B20: ALIAS / ES | E20: =RTC!E20 -> Risa
B21: SEX | E21: =RTC!E21 -> Female
B22: AGE | E22: =RTC!E22 -> 51
B23: CIVIL STATUS | E23: =RTC!E23 -> n/a
B24: DATE OF BIRTH | E24: =RTC!E24 -> 25073
B25: PLACE OF BIRTH | E25: =RTC!E25 -> Ermita, Cebu City, Cebu
B26: PRESENT ADDRESS | E26: =RTC!E26 -> detained at PNP Cordova, Cebu
B27: PERMANENT ADDRESS | E27: =RTC!E27 -> 25D Ermita Beach, Cebu City, Cebu
B28: CRIMINAL CASE NO. / S | E28: =RTC!E28 -> COR-38395 and COR-38397
B29: OFFENSES | E29: =RTC!E29 -> Violation of Secs. 5 & 11 of RA 9165
... B32: NAME OF PARENTS | E32: =RTC!E32 -> n/a
E33: =RTC!E33 -> n/a
F35: {Investigating_Officer}
F36: Investigating Officer-on-Case
A37: Noted:
B39: Chief Probation and Parole Officer
F42: Date
A43: TO: | B43: {Office_Name}
B44: IBP Bldg., E.B. Aumentado St., Tagbilaran City, Bohol
A46: FROM: | B46: =B11 -> THE CHIEF, PNP-CRMEU
B47: Tagbilaran City PNP
B48: Tagbilaran City, Bohol
A49: Records check revealed the following as of this date:
B50: ( ) No records on file
B51: ( ) No derogatory record
B52: ( ) Derogatory record stated at the back of this page
...

Sheet Brgy
A1: PPA Form 13 | G1: PPA-FO-FR-013
A4: {Office_Name}
A5: Tagbilaran City Parole and Probation Office
A6: IBP Building, New Capitol Site, Tagbilaran City
A7: Tel No. (038) 500-1146 ppo07.tagbilarancity@gmail.com https://probation.gov.ph
A8: REQUEST FOR RECORDS CHECK
G10: DATE: | H10: =RTC!H10 -> 43777
A11: TO: | B11: The Barangay Chairman
B12: Ermita
B13: Cebu City
A15: SIR/MA'AM:
B16: May we be furnished derogatory records of the applicant for probation named below:
B18: NAME OF PETITIONER | E18: =RTC!E18 -> RISALINDA PACA ABELLAR
B19: TRUE NAME | E19: =RTC!E19 -> RISALINDA PACA ABELLAR
B20: ALIAS / ES | E20: =RTC!E20 -> Risa
B21: SEX | E21: =RTC!E21 -> Female
B22: AGE | E22: =RTC!E22 -> 51
B23: CIVIL STATUS | E23: =RTC!E23 -> n/a
B24: DATE OF BIRTH | E24: =RTC!E24 -> 25073
B25: PLACE OF BIRTH | E25: =RTC!E25 -> Ermita, Cebu City, Cebu
B26: PRESENT ADDRESS | E26: =RTC!E26 -> detained at PNP Cordova, Cebu
B27: PERMANENT ADDRESS | E27: =RTC!E27 -> 25D Ermita Beach, Cebu City, Cebu
B28: CRIMINAL CASE NO. / S | E28: =RTC!E28 -> COR-38395 and COR-38397
B29: OFFENSES | E29: =RTC!E29 -> Violation of Secs. 5 & 11 of RA 9165
... B32: NAME OF PARENTS | E32: =RTC!E32 -> n/a
E33: =RTC!E33 -> n/a
F35: {Investigating_Officer}
F36: Investigating Officer-on-Case
A37: Noted:
B39: Chief Probation and Parole Officer
F42: Date
A43: TO: | B43: {Office_Name}
B44: IBP Bldg., E.B. Aumentado St., Tagbilaran City, Bohol
A46: FROM: | B46: =B11 -> The Barangay Chairman
B47: =B12 -> Ermita
B48: =B13 -> Cebu City
A49: Records check revealed the following as of this date:
B50: ( ) No records on file
B51: ( ) No derogatory record
B52: ( ) Derogatory record stated at the back of this page
...

Sheet NBI
A1: PPA Form 13 | G1: PPA-FO-FR-013
A4: {Office_Name}
A5: Tagbilaran City Parole and Probation Office
A6: IBP Building, New Capitol Site, Tagbilaran City
A7: Tel No. (038) 500-1146 ppo07.tagbilarancity@gmail.com https://probation.gov.ph
A8: REQUEST FOR RECORDS CHECK
G10: DATE: | H10: =RTC!H10 -> 43777
A11: TO: | B11: The Chief
B12: Identification & Records Section
B13: NBI - Manila
A15: SIR/MA'AM:
B16: May we be furnished derogatory records of the applicant for probation named below:
B18: NAME OF PETITIONER | E18: =RTC!E18 -> RISALINDA PACA ABELLAR
B19: TRUE NAME | E19: =RTC!E19 -> RISALINDA PACA ABELLAR
B20: ALIAS / ES | E20: =RTC!E20 -> Risa
B21: SEX | E21: =RTC!E21 -> Female
B22: AGE | E22: =RTC!E22 -> 51
B23: CIVIL STATUS | E23: =RTC!E23 -> n/a
B24: DATE OF BIRTH | E24: =RTC!E24 -> 25073
B25: PLACE OF BIRTH | E25: =RTC!E25 -> Ermita, Cebu City, Cebu
B26: PRESENT ADDRESS | E26: =RTC!E26 -> detained at PNP Cordova, Cebu
B27: PERMANENT ADDRESS | E27: =RTC!E27 -> 25D Ermita Beach, Cebu City, Cebu
B28: CRIMINAL CASE NO. / S | E28: =RTC!E28 -> COR-38395 and COR-38397
B29: OFFENSES | E29: =RTC!E29 -> Violation of Secs. 5 & 11 of RA 9165
... B32: NAME OF PARENTS | E32: =RTC!E32 -> n/a
E33: =RTC!E33 -> n/a
F35: {Investigating_Officer}
F36: Investigating Officer-on-Case
A37: Noted:
B39: Chief Probation and Parole Officer
F42: Date
A43: TO: | B43: {Office_Name}
B44: IBP Bldg., E.B. Aumentado St., Tagbilaran City, Bohol
A46: FROM: | B46: =B11 -> The Chief
B47: =B12 -> Identification & Records Section
B48: =B13 -> NBI - Manila
A49: Records check revealed the following as of this date:
B50: ( ) No records on file
B51: ( ) No derogatory record
B52: ( ) Derogatory record stated at the back of this page
...

Sheet Others
A1: PPA Form 13 | G1: PPA-FO-FR-013
A4: {Office_Name}
A5: Tagbilaran City Parole and Probation Office
A6: IBP Building, New Capitol Site, Tagbilaran City
A7: Tel No. (038) 500-1146 ppo07.tagbilarancity@gmail.com https://probation.gov.ph
A8: REQUEST FOR RECORDS CHECK
G10: DATE: | H10: =RTC!H10 -> 43777
A11: TO: | B11: The Records Officer
B12: Cebu City Jail- Female Dormitory
B13: Tagbilaran City, Bohol
A15: SIR/MA'AM:
B16: May we be furnished derogatory records of the applicant for probation named below:
B18: NAME OF PETITIONER | E18: =RTC!E18 -> RISALINDA PACA ABELLAR
B19: TRUE NAME | E19: =RTC!E19 -> RISALINDA PACA ABELLAR
B20: ALIAS / ES | E20: =RTC!E20 -> Risa
B21: SEX | E21: =RTC!E21 -> Female
B22: AGE | E22: =RTC!E22 -> 51
B23: CIVIL STATUS | E23: =RTC!E23 -> n/a
B24: DATE OF BIRTH | E24: =RTC!E24 -> 25073
B25: PLACE OF BIRTH | E25: =RTC!E25 -> Ermita, Cebu City, Cebu
B26: PRESENT ADDRESS | E26: =RTC!E26 -> detained at PNP Cordova, Cebu
B27: PERMANENT ADDRESS | E27: =RTC!E27 -> 25D Ermita Beach, Cebu City, Cebu
B28: CRIMINAL CASE NO. / S | E28: =RTC!E28 -> COR-38395 and COR-38397
B29: OFFENSES | E29: =RTC!E29 -> Violation of Secs. 5 & 11 of RA 9165
... B32: NAME OF PARENTS | E32: =RTC!E32 -> n/a
E33: =RTC!E33 -> n/a
F35: {Investigating_Officer}
F36: Investigating Officer-on-Case
A37: Noted:
B39: Chief Probation and Parole Officer
F42: Date
A43: TO: | B43: {Office_Name}
B44: IBP Bldg., E.B. Aumentado St., Tagbilaran City, Bohol
A46: FROM: | B46: =B11 -> The Records Officer
B47: =B12 -> Cebu City Jail- Female Dormitory
B48: =B13 -> Tagbilaran City, Bohol
A49: Records check revealed the following as of this date:
B50: ( ) No records on file
B51: ( ) No derogatory record
B52: ( ) Derogatory record stated at the back of this page
...
